2017-01-19 22:35:45,532 INFO: microblog startup [in /Users/ruizhang/Dropbox/micro_blog/app/__init__.py:36]
2017-01-20 10:17:18,577 INFO: microblog startup [in /Users/ruizhang/Dropbox/micro_blog/app/__init__.py:36]
2017-01-20 10:17:41,159 ERROR: Exception on /authorize/twitter [GET] [in /Users/ruizhang/anaconda/lib/python2.7/site-packages/flask/app.py:1423]
Traceback (most recent call last):
  File "/Users/ruizhang/anaconda/lib/python2.7/site-packages/flask/app.py", line 1817, in wsgi_app
    response = self.full_dispatch_request()
  File "/Users/ruizhang/anaconda/lib/python2.7/site-packages/flask/app.py", line 1477, in full_dispatch_request
    rv = self.handle_user_exception(e)
  File "/Users/ruizhang/anaconda/lib/python2.7/site-packages/flask/app.py", line 1381, in handle_user_exception
    reraise(exc_type, exc_value, tb)
  File "/Users/ruizhang/anaconda/lib/python2.7/site-packages/flask/app.py", line 1475, in full_dispatch_request
    rv = self.dispatch_request()
  File "/Users/ruizhang/anaconda/lib/python2.7/site-packages/flask/app.py", line 1461, in dispatch_request
    return self.view_functions[rule.endpoint](**req.view_args)
  File "/Users/ruizhang/Dropbox/micro_blog/app/views.py", line 107, in oauth_authorize
    return oauth.authorize()
  File "/Users/ruizhang/Dropbox/micro_blog/app/oauth.py", line 86, in authorize
    params={'oauth_callback': self.get_callback_url()}
  File "/Users/ruizhang/anaconda/lib/python2.7/site-packages/rauth/service.py", line 244, in get_request_token
    process_token_request(r, decoder, key_token, key_token_secret)
  File "/Users/ruizhang/anaconda/lib/python2.7/site-packages/rauth/service.py", line 24, in process_token_request
    raise KeyError(PROCESS_TOKEN_ERROR.format(key=bad_key, raw=r.content))
KeyError: 'Decoder failed to handle oauth_token with data as returned by provider. A different decoder may be needed. Provider returned: {"errors":[{"code":32,"message":"Could not authenticate you."}]}'
